<!--
 ~ Copyright 2019 The ROBEL Authors.
 ~
 ~ Licensed under the Apache License, Version 2.0 (the "License");
 ~ you may not use this file except in compliance with the License.
 ~ You may obtain a copy of the License at
 ~
 ~     http://www.apache.org/licenses/LICENSE-2.0
 ~
 ~ Unless required by applicable law or agreed to in writing, software
 ~ distributed under the License is distributed on an "AS IS" BASIS,
 ~ WITHOUT WARRANTIES OR CONDITIONS OF ANY KIND, either express or implied.
 ~ See the License for the specific language governing permissions and
 ~ limitations under the License.
 -->

<?xml version="1.0"?>
<mujoco model="dkitty-v2.1">
  <compiler meshdir="./../../robel-scenes/dkitty" texturedir="../../robel-scenes/dkitty"/>
  <include file="./../../robel-scenes/scenes/basic_scene.xml"/>
  <include file="./../../robel-scenes/dkitty/assets/dependenciesA_xh-v2.1.xml"/>
  <asset>
    <hfield name="hf1" size="4.5 4.5 1 .1" nrow="120" ncol="120"/>
  </asset>
  <worldbody>
    <site name="target" pos="1 0 0" type="cylinder" size=".5 .005 0" rgba="0 1 0 1"/>
    <site name="heading" pos="1 0 0.25" type="cylinder" size=".05 .35 0" rgba="1 1 0 1"/>
    <geom name="hfield1" type="hfield" hfield="hf1" pos="0 0 -.005" material="MatPlane" rgba=".7 .7 .7 1"/>
    <body name="fence" pos="0 0 0">
      <geom name="top_fence" type="box" pos="0 1.3 0.3" size="2.025 0.05 0.3" material="MatPlane" rgba=".1 .1 .9 1"/>
      <geom name="bottom_fence" type="box" pos="0 -1.3 0.3" size="2.025 0.05 0.3" material="MatPlane" rgba=".1 .1 .9 1"/>
      <geom name="right_fence" type="box" pos="2 0 0.3" size="0.05 1.325 0.3" material="MatPlane" rgba=".1 .1 .9 1"/>
      <geom name="left_fence" type="box" pos="-2 0 0.3" size="0.05 1.325 0.3" material="MatPlane" rgba=".1 .1 .9 1"/>
    </body>
    <body name="kitty_frame" pos="0 0 .3">
      <camera name="trackingZ" pos="0 0 3" zaxis="0 0 3" mode="trackcom"/>
      <camera name="trackingY" pos="1.5 1.5 0.35" xyaxes="-.7 -1 0 0 -.3 -1" mode="trackcom"/>
      <site name="torso" type="box" size=".090 .150 .007" group="4"/>
      <geom type="sphere" size="0.010" mass="0.010" group="4"/>
      <joint name="Tx" pos="0 0 0" axis="1 0 0" limited="true" type="slide" range="-10 10"/>
      <joint name="Ty" pos="0 0 0" axis="0 1 0" limited="true" type="slide" range="-10 10"/>
      <joint name="Tz" pos="0 0 0" axis="0 0 1" limited="true" type="slide" range="-2 2"/>
      <joint name="Rx" pos="0 0 0" axis="1 0 0" limited="true" range="-3.14 3.14"/>
      <joint name="Ry" pos="0 0 0" axis="0 1 0" limited="true" range="-3.14 3.14"/>
      <joint name="Rz" pos="0 0 0" axis="0 0 1" limited="true" range="-3.14 3.14"/>
      <include file="./../../robel-scenes/dkitty/assets/chainA_xh-v2.1.xml"/>
    </body>
    <body name="ball" pos="0.5 0 0.4">
      <geom name="ball" type="sphere" size="0.2" rgba="0.9 0. 0.9 1" mass="0.3" group="4"/>
      <site name="ball" type="sphere" size="0.2" rgba="0.9 0. 0.9 1"/>
      <freejoint/>
    </body>
    <body name="ball2" pos="0 -0.5 0.4">
      <geom name="ball2" type="sphere" size="0.2" rgba="0.9 0. 0.9 1" mass="0.3" group="4"/>
      <site name="ball2" type="sphere" size="0.2" rgba="0.9 0. 0.9 1"/>
      <freejoint/>
    </body>
    <body name="seesaw" pos="1 0.95 0.2" euler="0 0 0.">
      <geom name="seesaw" type="box" size="0.8 0.3 0.02" rgba="0.9 0. 0.9 1" mass="0.1" group="4"/>
      <site name="seesaw" type="box" size="0.8 0.3 0.02" rgba="0.9 0. 0.0 1"/>
      <joint type="hinge" axis="0 1 0" limited="false" pos="0.2 0 0"/>
    </body>
    <body name="seesaw2" pos="-0.7 -0.2 0.2" euler="0 0 -0.7">
      <geom name="seesaw2" type="box" size="0.8 0.3 0.02" rgba="0.9 0. 0.9 1" mass="0.1" group="4"/>
      <site name="seesaw2" type="box" size="0.8 0.3 0.02" rgba="0.9 0. 0.0 1"/>
      <joint type="hinge" axis="0 1 0" limited="false" pos="-0.2 0 0"/>
    </body>
  </worldbody>
</mujoco>
